Workbook

Sheet Dashboard
B2: EXECUTIVE SALES & ANALYTICS DASHBOARD
B4: Source: Sales Data | Period: Jan 2026 - Aug 2026 | All figures in ₹

Sheet Sales Data
A1: Order ID | B1: Date | C1: Customer | D1: City | E1: State | F1: Product | G1: Category | H1: Quantity | I1: Unit Price | J1: Discount | K1: Sales | L1: Profit | M1: Payment Mode
A2: ORD0095 | B2: 46024 | C2: Pooja | D2: Agra | E2: Uttar Pradesh | F2: Notebook | G2: Stationery | H2: 4 | I2: 250 | J2: 0.15 | K2: 850 | L2: 255 | M2: EMI
A3: ORD0119 | B3: 46025 | C3: Vikas | D3: Hyderabad | E3: Telangana | F3: Smartphone | G3: Electronics | H3: 2 | I3: 25000 | J3: 0.15 | K3: 42500 | L3: 3400 | M3: Net Banking
A4: ORD0069 | B4: 46029 | C4: Vikas | D4: Kolkata | E4: West Bengal | F4: Desk | G4: Furniture | H4: 3 | I4: 12000 | J4: 0.1 | K4: 32400 | L4: 3888 | M4: UPI
A5: ORD0066 | B5: 46029 | C5: Arjun | D5: Pune | E5: Maharashtra | F5: Notebook | G5: Stationery | H5: 4 | I5: 250 | J5: 0.05 | K5: 950 | L5: 285 | M5: Cash
A6: ORD0117 | B6: 46030 | C6: Arjun | D6: Bengaluru | E6: Karnataka | F6: Headphones | G6: Electronics | H6: 4 | I6: 2500 | J6: 0.05 | K6: 9500 | L6: 1900 | M6: Cash
A7: ORD0138 | B7: 46031 | C7: Pooja | D7: Jaipur | E7: Rajasthan | F7: USB Drive | G7: Accessories | H7: 3 | I7: 800 | J7: 0.15 | K7: 2040 | L7: 489.6 | M7: UPI
A8: ORD0169 | B8: 46032 | C8: Amit | D8: Chennai | E8: Tamil Nadu | F8: Keyboard | G8: Electronics | H8: 3 | I8: 1800 | J8: 0.05 | K8: 5130 | L8: 923.4 | M8: UPI
A9: ORD0146 | B9: 46033 | C9: Sneha | D9: Surat | E9: Gujarat | F9: Bookshelf | G9: Furniture | H9: 5 | I9: 7000 | J9: 0.15 | K9: 29750 | L9: 4462.5 | M9: Cash
A10: ORD0074 | B10: 46034 | C10: Riya | D10: Ahmedabad | E10: Gujarat | F10: Laptop | G10: Electronics | H10: 5 | I10: 55000 | J10: 0.05 | K10: 261250 | L10: 26125 | M10: Cash
A11: ORD0171 | B11: 46034 | C11: Priya | D11: Agra | E11: Uttar Pradesh | F11: Monitor | G11: Electronics | H11: 3 | I11: 14000 | J11: 0.1 | K11: 37800 | L11: 4536 | M11: Net Banking
A12: ORD0010 | B12: 46034 | C12: Anjali | D12: Kolkata | E12: West Bengal | F12: Notebook | G12: Stationery | H12: 3 | I12: 250 | J12: 0 | K12: 750 | L12: 225 | M12: Card
A13: ORD0045 | B13: 46037 | C13: Varun | D13: Delhi | E13: Delhi | F13: Bookshelf | G13: Furniture | H13: 5 | I13: 7000 | J13: 0.05 | K13: 33250 | L13: 4987.5 | M13: UPI
... A201: ORD0061 | B201: 46264 | C201: Rohit | D201: Bhopal | E201: Madhya Pradesh | F201: Printer | G201: Electronics | H201: 1 | I201: 12000 | J201: 0.1 | K201: 10800 | L201: 1080 | M201: EMI

Sheet Pivot Table
A1: Category | B1: Sum of Sales | J1: Top Cities by Sales
A2: Accessories | B2: 152660 | J2: Label | K2: Sales
A3: Electronics | B3: 4130025 | J3: Kolkata | K3: =SUMIFS('Sales Data'!$K$2:$K$201,'Sales Data'!$D$2:$D$201,J3) -> 762847.5
A4: Furniture | B4: 1056725 | J4: Ahmedabad | K4: =SUMIFS('Sales Data'!$K$2:$K$201,'Sales Data'!$D$2:$D$201,J4) -> 717970
A5: Home | B5: 44000 | J5: Bengaluru | K5: =SUMIFS('Sales Data'!$K$2:$K$201,'Sales Data'!$D$2:$D$201,J5) -> 610375
A6: Stationery | B6: 19559 | J6: Delhi | K6: =SUMIFS('Sales Data'!$K$2:$K$201,'Sales Data'!$D$2:$D$201,J6) -> 575840
A7: Total Result | B7: 5402969 | J7: Mumbai | K7: =SUMIFS('Sales Data'!$K$2:$K$201,'Sales Data'!$D$2:$D$201,J7) -> 446037.5
J8: Jaipur | K8: =SUMIFS('Sales Data'!$K$2:$K$201,'Sales Data'!$D$2:$D$201,J8) -> 421632.5
B9: Product | C9: Sum of Sales | J9: Lucknow | K9: =SUMIFS('Sales Data'!$K$2:$K$201,'Sales Data'!$D$2:$D$201,J9) -> 395363
B10: Backpack | C10: 95260 | J10: Pune | K10: =SUMIFS('Sales Data'!$K$2:$K$201,'Sales Data'!$D$2:$D$201,J10) -> 287452
B11: Bookshelf | C11: 326550
B12: Desk | C12: 431400 | J12: Top Customers by Sales
B13: Headphones | C13: 79125 | J13: Label | K13: Sales
B14: Keyboard | C14: 101700 | J14: Riya | K14: =SUMIFS('Sales Data'!$K$2:$K$201,'Sales Data'!$C$2:$C$201,J14) -> 602280
B15: Laptop | C15: 2134000 | J15: Saurabh | K15: =SUMIFS('Sales Data'!$K$2:$K$201,'Sales Data'!$C$2:$C$201,J15) -> 547790
B16: Monitor | C16: 529200 | J16: Arjun | K16: =SUMIFS('Sales Data'!$K$2:$K$201,'Sales Data'!$C$2:$C$201,J16) -> 483192.5
B17: Mouse | C17: 33840 | J17: Priya | K17: =SUMIFS('Sales Data'!$K$2:$K$201,'Sales Data'!$C$2:$C$201,J17) -> 461007.5
B18: Notebook | C18: 11675 | D18: City | E18: Sum of Sales | J18: Meena | K18: =SUMIFS('Sales Data'!$K$2:$K$201,'Sales Data'!$C$2:$C$201,J18) -> 423747.5
B19: Office Chair | C19: 298775 | D19: Agra | E19: 124065 | J19: Kavita | K19: =SUMIFS('Sales Data'!$K$2:$K$201,'Sales Data'!$C$2:$C$201,J19) -> 383060
B20: Pen Set | C20: 7884 | D20: Ahmedabad | E20: 717970 | J20: Vikas | K20: =SUMIFS('Sales Data'!$K$2:$K$201,'Sales Data'!$C$2:$C$201,J20) -> 378530
B21: Printer | C21: 246000 | D21: Bengaluru | E21: 610375 | J21: Nikhil | K21: =SUMIFS('Sales Data'!$K$2:$K$201,'Sales Data'!$C$2:$C$201,J21) -> 328360
B22: Smartphone | C22: 1040000 | D22: Bhopal | E22: 145430
B23: Table Lamp | C23: 44000 | D23: Chennai | E23: 180447.5 | J23: Sales by Category
B24: USB Drive | C24: 23560 | D24: Delhi | E24: 575840 | J24: Label | K24: Sales
B25: Total Result | C25: 5402969 | D25: Hyderabad | E25: 194530 | J25: Electronics | K25: =SUMIFS('Sales Data'!$K$2:$K$201,'Sales Data'!$G$2:$G$201,J25) -> 4130025
D26: Indore | E26: 241715 | J26: Furniture | K26: =SUMIFS('Sales Data'!$K$2:$K$201,'Sales Data'!$G$2:$G$201,J26) -> 1056725
D27: Jaipur | E27: 421632.5 | J27: Accessories | K27: =SUMIFS('Sales Data'!$K$2:$K$201,'Sales Data'!$G$2:$G$201,J27) -> 152660
D28: Kolkata | E28: 762847.5 | J28: Home | K28: =SUMIFS('Sales Data'!$K$2:$K$201,'Sales Data'!$G$2:$G$201,J28) -> 44000
D29: Lucknow | E29: 395363 | J29: Stationery | K29: =SUMIFS('Sales Data'!$K$2:$K$201,'Sales Data'!$G$2:$G$201,J29) -> 19559
D30: Mathura | E30: 46549
D31: Mumbai | E31: 446037.5 | J31: Top Products by Sales
D32: Pune | E32: 287452 | G32: Payment Mode | H32: Sum of Sales | J32: Label | K32: Sales
D33: Surat | E33: 252715 | G33: Card | H33: 906145 | J33: Laptop | K33: =SUMIFS('Sales Data'!$K$2:$K$201,'Sales Data'!$F$2:$F$201,J33) -> 2134000
D34: Total Result | E34: 5402969 | G34: Cash | H34: 959975 | J34: Smartphone | K34: =SUMIFS('Sales Data'!$K$2:$K$201,'Sales Data'!$F$2:$F$201,J34) -> 1040000
G35: EMI | H35: 735322.5 | J35: Monitor | K35: =SUMIFS('Sales Data'!$K$2:$K$201,'Sales Data'!$F$2:$F$201,J35) -> 529200
G36: Net Banking | H36: 1108051.5 | J36: Desk | K36: =SUMIFS('Sales Data'!$K$2:$K$201,'Sales Data'!$F$2:$F$201,J36) -> 431400
G37: UPI | H37: 1693475 | J37: Bookshelf | K37: =SUMIFS('Sales Data'!$K$2:$K$201,'Sales Data'!$F$2:$F$201,J37) -> 326550
G38: Total Result | H38: 5402969 | J38: Office Chair | K38: =SUMIFS('Sales Data'!$K$2:$K$201,'Sales Data'!$F$2:$F$201,J38) -> 298775
J39: Printer | K39: =SUMIFS('Sales Data'!$K$2:$K$201,'Sales Data'!$F$2:$F$201,J39) -> 246000
J40: Keyboard | K40: =SUMIFS('Sales Data'!$K$2:$K$201,'Sales Data'!$F$2:$F$201,J40) -> 101700
...
